Workbook

Sheet Executive Dashboard
A1: Stock Name | B1: Average Annual Return | C1: Annualized Volatility | D1: 5 Year Trend
A2: TCS | B2: =TCS!F2 -> -0.070153232 | C2: =TCS!E2 -> 0.21880103
A3: INFOSYS | B3: =INFOSYS!F2 -> -0.048925878 | C3: =INFOSYS!E2 -> 0.25480536
A4: HDFC | B4: =HDFC!F2 -> 0.032279813 | C4: =HDFC!E2 -> 0.20937815
A5: ICICI | B5: =ICICI!F2 -> 0.174235 | C5: =ICICI!E2 -> 0.20404637

Sheet TCS
A1: =IFERROR(__xludf.DUMMYFUNCTION("GOOGLEFINANCE(""NSE:TCS"", ""price"", TODAY()-1825, TODAY(), ""DAILY"")"),"Date") -> Date | B1: =IFERROR(__xludf.DUMMYFUNCTION("""COMPUTED_VALUE"""),"Close") -> Close | C1: Daily Return % | D1: 50-Day Moving Average (SMA) | E1: Annualized Volatility (Risk) | F1: Average Annual Return
A2: =IFERROR(__xludf.DUMMYFUNCTION("""COMPUTED_VALUE"""),44375.6458333333) -> 44375.646 | B2: =IFERROR(__xludf.DUMMYFUNCTION("""COMPUTED_VALUE"""),3336.75) -> 3336.75 | E2: =_xlfn.STDEV.S(C:C) * SQRT(252) -> 0.21880103 | F2: =AVERAGE(C:C)*252 -> -0.070153232
A3: =IFERROR(__xludf.DUMMYFUNCTION("""COMPUTED_VALUE"""),44376.6458333333) -> 44376.646 | B3: =IFERROR(__xludf.DUMMYFUNCTION("""COMPUTED_VALUE"""),3340.85) -> 3340.85 | C3: =(B3-B2)/B2 -> 0.0012287405
A4: =IFERROR(__xludf.DUMMYFUNCTION("""COMPUTED_VALUE"""),44377.6458333333) -> 44377.646 | B4: =IFERROR(__xludf.DUMMYFUNCTION("""COMPUTED_VALUE"""),3345.75) -> 3345.75 | C4: =(B4-B3)/B3 -> 0.0014666926
A5: =IFERROR(__xludf.DUMMYFUNCTION("""COMPUTED_VALUE"""),44378.6458333333) -> 44378.646 | B5: =IFERROR(__xludf.DUMMYFUNCTION("""COMPUTED_VALUE"""),3341.5) -> 3341.5 | C5: =(B5-B4)/B4 -> -0.0012702683
A6: =IFERROR(__xludf.DUMMYFUNCTION("""COMPUTED_VALUE"""),44379.6458333333) -> 44379.646 | B6: =IFERROR(__xludf.DUMMYFUNCTION("""COMPUTED_VALUE"""),3325.45) -> 3325.45 | C6: =(B6-B5)/B5 -> -0.0048032321
A7: =IFERROR(__xludf.DUMMYFUNCTION("""COMPUTED_VALUE"""),44382.6458333333) -> 44382.646 | B7: =IFERROR(__xludf.DUMMYFUNCTION("""COMPUTED_VALUE"""),3321) -> 3321 | C7: =(B7-B6)/B6 -> -0.0013381648
A8: =IFERROR(__xludf.DUMMYFUNCTION("""COMPUTED_VALUE"""),44383.6458333333) -> 44383.646 | B8: =IFERROR(__xludf.DUMMYFUNCTION("""COMPUTED_VALUE"""),3262.3) -> 3262.3 | C8: =(B8-B7)/B7 -> -0.017675399
A9: =IFERROR(__xludf.DUMMYFUNCTION("""COMPUTED_VALUE"""),44384.6458333333) -> 44384.646 | B9: =IFERROR(__xludf.DUMMYFUNCTION("""COMPUTED_VALUE"""),3274.95) -> 3274.95 | C9: =(B9-B8)/B8 -> 0.0038776323
A10: =IFERROR(__xludf.DUMMYFUNCTION("""COMPUTED_VALUE"""),44385.6458333333) -> 44385.646 | B10: =IFERROR(__xludf.DUMMYFUNCTION("""COMPUTED_VALUE"""),3258.5) -> 3258.5 | C10: =(B10-B9)/B9 -> -0.0050229775
A11: =IFERROR(__xludf.DUMMYFUNCTION("""COMPUTED_VALUE"""),44386.6458333333) -> 44386.646 | B11: =IFERROR(__xludf.DUMMYFUNCTION("""COMPUTED_VALUE"""),3208.15) -> 3208.15 | C11: =(B11-B10)/B10 -> -0.015451895
A12: =IFERROR(__xludf.DUMMYFUNCTION("""COMPUTED_VALUE"""),44389.6458333333) -> 44389.646 | B12: =IFERROR(__xludf.DUMMYFUNCTION("""COMPUTED_VALUE"""),3193.1) -> 3193.1 | C12: =(B12-B11)/B11 -> -0.0046911772
A13: =IFERROR(__xludf.DUMMYFUNCTION("""COMPUTED_VALUE"""),44390.6458333333) -> 44390.646 | B13: =IFERROR(__xludf.DUMMYFUNCTION("""COMPUTED_VALUE"""),3187.55) -> 3187.55 | C13: =(B13-B12)/B12 -> -0.0017381228
A14: =IFERROR(__xludf.DUMMYFUNCTION("""COMPUTED_VALUE"""),44391.6458333333) -> 44391.646 | B14: =IFERROR(__xludf.DUMMYFUNCTION("""COMPUTED_VALUE"""),3214.55) -> 3214.55 | C14: =(B14-B13)/B13 -> 0.0084704554
A15: =IFERROR(__xludf.DUMMYFUNCTION("""COMPUTED_VALUE"""),44392.6458333333) -> 44392.646 | B15: =IFERROR(__xludf.DUMMYFUNCTION("""COMPUTED_VALUE"""),3202.95) -> 3202.95 | C15: =(B15-B14)/B14 -> -0.0036085922
A16: =IFERROR(__xludf.DUMMYFUNCTION("""COMPUTED_VALUE"""),44393.6458333333) -> 44393.646 | B16: =IFERROR(__xludf.DUMMYFUNCTION("""COMPUTED_VALUE"""),3194.8) -> 3194.8 | C16: =(B16-B15)/B15 -> -0.0025445293
A17: =IFERROR(__xludf.DUMMYFUNCTION("""COMPUTED_VALUE"""),44396.6458333333) -> 44396.646 | B17: =IFERROR(__xludf.DUMMYFUNCTION("""COMPUTED_VALUE"""),3184.6) -> 3184.6 | C17: =(B17-B16)/B16 -> -0.0031926881
A18: =IFERROR(__xludf.DUMMYFUNCTION("""COMPUTED_VALUE"""),44397.6458333333) -> 44397.646 | B18: =IFERROR(__xludf.DUMMYFUNCTION("""COMPUTED_VALUE"""),3205.8) -> 3205.8 | C18: =(B18-B17)/B17 -> 0.006657037
A19: =IFERROR(__xludf.DUMMYFUNCTION("""COMPUTED_VALUE"""),44399.6458333333) -> 44399.646 | B19: =IFERROR(__xludf.DUMMYFUNCTION("""COMPUTED_VALUE"""),3216.35) -> 3216.35 | C19: =(B19-B18)/B18 -> 0.0032909102
A20: =IFERROR(__xludf.DUMMYFUNCTION("""COMPUTED_VALUE"""),44400.6458333333) -> 44400.646 | B20: =IFERROR(__xludf.DUMMYFUNCTION("""COMPUTED_VALUE"""),3212.85) -> 3212.85 | C20: =(B20-B19)/B19 -> -0.00108819
A21: =IFERROR(__xludf.DUMMYFUNCTION("""COMPUTED_VALUE"""),44403.6458333333) -> 44403.646 | B21: =IFERROR(__xludf.DUMMYFUNCTION("""COMPUTED_VALUE"""),3197.55) -> 3197.55 | C21: =(B21-B20)/B20 -> -0.0047621271
A22: =IFERROR(__xludf.DUMMYFUNCTION("""COMPUTED_VALUE"""),44404.6458333333) -> 44404.646 | B22: =IFERROR(__xludf.DUMMYFUNCTION("""COMPUTED_VALUE"""),3182.95) -> 3182.95 | C22: =(B22-B21)/B21 -> -0.0045659958
A23: =IFERROR(__xludf.DUMMYFUNCTION("""COMPUTED_VALUE"""),44405.6458333333) -> 44405.646 | B23: =IFERROR(__xludf.DUMMYFUNCTION("""COMPUTED_VALUE"""),3197.8) -> 3197.8 | C23: =(B23-B22)/B22 -> 0.0046654833
A24: =IFERROR(__xludf.DUMMYFUNCTION("""COMPUTED_VALUE"""),44406.6458333333) -> 44406.646 | B24: =IFERROR(__xludf.DUMMYFUNCTION("""COMPUTED_VALUE"""),3195.8) -> 3195.8 | C24: =(B24-B23)/B23 -> -0.00062542998
A25: =IFERROR(__xludf.DUMMYFUNCTION("""COMPUTED_VALUE"""),44407.6458333333) -> 44407.646 | B25: =IFERROR(__xludf.DUMMYFUNCTION("""COMPUTED_VALUE"""),3167.45) -> 3167.45 | C25: =(B25-B24)/B24 -> -0.0088710182
A26: =IFERROR(__xludf.DUMMYFUNCTION("""COMPUTED_VALUE"""),44410.6458333333) -> 44410.646 | B26: =IFERROR(__xludf.DUMMYFUNCTION("""COMPUTED_VALUE"""),3219.4) -> 3219.4 | C26: =(B26-B25)/B25 -> 0.016401206
A27: =IFERROR(__xludf.DUMMYFUNCTION("""COMPUTED_VALUE"""),44411.6458333333) -> 44411.646 | B27: =IFERROR(__xludf.DUMMYFUNCTION("""COMPUTED_VALUE"""),3284.9) -> 3284.9 | C27: =(B27-B26)/B26 -> 0.020345406
A28: =IFERROR(__xludf.DUMMYFUNCTION("""COMPUTED_VALUE"""),44412.6458333333) -> 44412.646 | B28: =IFERROR(__xludf.DUMMYFUNCTION("""COMPUTED_VALUE"""),3273.95) -> 3273.95 | C28: =(B28-B27)/B27 -> -0.0033334348
A29: =IFERROR(__xludf.DUMMYFUNCTION("""COMPUTED_VALUE"""),44413.6458333333) -> 44413.646 | B29: =IFERROR(__xludf.DUMMYFUNCTION("""COMPUTED_VALUE"""),3283.95) -> 3283.95 | C29: =(B29-B28)/B28 -> 0.0030544144
A30: =IFERROR(__xludf.DUMMYFUNCTION("""COMPUTED_VALUE"""),44414.6458333333) -> 44414.646 | B30: =IFERROR(__xludf.DUMMYFUNCTION("""COMPUTED_VALUE"""),3309.8) -> 3309.8 | C30: =(B30-B29)/B29 -> 0.007871618
A31: =IFERROR(__xludf.DUMMYFUNCTION("""COMPUTED_VALUE"""),44417.6458333333) -> 44417.646 | B31: =IFERROR(__xludf.DUMMYFUNCTION("""COMPUTED_VALUE"""),3322.7) -> 3322.7 | C31: =(B31-B30)/B30 -> 0.0038975165
A32: =IFERROR(__xludf.DUMMYFUNCTION("""COMPUTED_VALUE"""),44418.6458333333) -> 44418.646 | B32: =IFERROR(__xludf.DUMMYFUNCTION("""COMPUTED_VALUE"""),3333.9) -> 3333.9 | C32: =(B32-B31)/B31 -> 0.0033707527
A33: =IFERROR(__xludf.DUMMYFUNCTION("""COMPUTED_VALUE"""),44419.6458333333) -> 44419.646 | B33: =IFERROR(__xludf.DUMMYFUNCTION("""COMPUTED_VALUE"""),3344.2) -> 3344.2 | C33: =(B33-B32)/B32 -> 0.0030894748
A34: =IFERROR(__xludf.DUMMYFUNCTION("""COMPUTED_VALUE"""),44420.6458333333) -> 44420.646 | B34: =IFERROR(__xludf.DUMMYFUNCTION("""COMPUTED_VALUE"""),3351.75) -> 3351.75 | C34: =(B34-B33)/B33 -> 0.0022576401
A35: =IFERROR(__xludf.DUMMYFUNCTION("""COMPUTED_VALUE"""),44421.6458333333) -> 44421.646 | B35: =IFERROR(__xludf.DUMMYFUNCTION("""COMPUTED_VALUE"""),3463.4) -> 3463.4 | C35: =(B35-B34)/B34 -> 0.033310957
A36: =IFERROR(__xludf.DUMMYFUNCTION("""COMPUTED_VALUE"""),44424.6458333333) -> 44424.646 | B36: =IFERROR(__xludf.DUMMYFUNCTION("""COMPUTED_VALUE"""),3472.95) -> 3472.95 | C36: =(B36-B35)/B35 -> 0.002757406
A37: =IFERROR(__xludf.DUMMYFUNCTION("""COMPUTED_VALUE"""),44425.6458333333) -> 44425.646 | B37: =IFERROR(__xludf.DUMMYFUNCTION("""COMPUTED_VALUE"""),3553.05) -> 3553.05 | C37: =(B37-B36)/B36 -> 0.023063966
A38: =IFERROR(__xludf.DUMMYFUNCTION("""COMPUTED_VALUE"""),44426.6458333333) -> 44426.646 | B38: =IFERROR(__xludf.DUMMYFUNCTION("""COMPUTED_VALUE"""),3560.55) -> 3560.55 | C38: =(B38-B37)/B37 -> 0.0021108625
A39: =IFERROR(__xludf.DUMMYFUNCTION("""COMPUTED_VALUE"""),44428.6458333333) -> 44428.646 | B39: =IFERROR(__xludf.DUMMYFUNCTION("""COMPUTED_VALUE"""),3559.5) -> 3559.5 | C39: =(B39-B38)/B38 -> -0.00029489826
A40: =IFERROR(__xludf.DUMMYFUNCTION("""COMPUTED_VALUE"""),44431.6458333333) -> 44431.646 | B40: =IFERROR(__xludf.DUMMYFUNCTION("""COMPUTED_VALUE"""),3637.4) -> 3637.4 | C40: =(B40-B39)/B39 -> 0.021885096
...

Sheet INFOSYS
A1: =IFERROR(__xludf.DUMMYFUNCTION("GOOGLEFINANCE(""NSE:INFY"", ""price"", TODAY()-1825, TODAY(), ""DAILY"")"),"Date") -> Date | B1: =IFERROR(__xludf.DUMMYFUNCTION("""COMPUTED_VALUE"""),"Close") -> Close | C1: Daily Return % | D1: 50-Day Moving Average (SMA) | E1: Annualized Volatility (Risk) | F1: Average Annual Return
A2: =IFERROR(__xludf.DUMMYFUNCTION("""COMPUTED_VALUE"""),44375.6458333333) -> 44375.646 | B2: =IFERROR(__xludf.DUMMYFUNCTION("""COMPUTED_VALUE"""),1571.8) -> 1571.8 | E2: =_xlfn.STDEV.S(C:C) * SQRT(252) -> 0.25480536 | F2: =AVERAGE(C:C)*252 -> -0.048925878
A3: =IFERROR(__xludf.DUMMYFUNCTION("""COMPUTED_VALUE"""),44376.6458333333) -> 44376.646 | B3: =IFERROR(__xludf.DUMMYFUNCTION("""COMPUTED_VALUE"""),1563.05) -> 1563.05 | C3: =(B3-B2)/B2 -> -0.005566866
A4: =IFERROR(__xludf.DUMMYFUNCTION("""COMPUTED_VALUE"""),44377.6458333333) -> 44377.646 | B4: =IFERROR(__xludf.DUMMYFUNCTION("""COMPUTED_VALUE"""),1580.8) -> 1580.8 | C4: =(B4-B3)/B3 -> 0.011356003
A5: =IFERROR(__xludf.DUMMYFUNCTION("""COMPUTED_VALUE"""),44378.6458333333) -> 44378.646 | B5: =IFERROR(__xludf.DUMMYFUNCTION("""COMPUTED_VALUE"""),1560.4) -> 1560.4 | C5: =(B5-B4)/B4 -> -0.012904858
A6: =IFERROR(__xludf.DUMMYFUNCTION("""COMPUTED_VALUE"""),44379.6458333333) -> 44379.646 | B6: =IFERROR(__xludf.DUMMYFUNCTION("""COMPUTED_VALUE"""),1567.8) -> 1567.8 | C6: =(B6-B5)/B5 -> 0.0047423738
A7: =IFERROR(__xludf.DUMMYFUNCTION("""COMPUTED_VALUE"""),44382.6458333333) -> 44382.646 | B7: =IFERROR(__xludf.DUMMYFUNCTION("""COMPUTED_VALUE"""),1578.95) -> 1578.95 | C7: =(B7-B6)/B6 -> 0.0071118765
A8: =IFERROR(__xludf.DUMMYFUNCTION("""COMPUTED_VALUE"""),44383.6458333333) -> 44383.646 | B8: =IFERROR(__xludf.DUMMYFUNCTION("""COMPUTED_VALUE"""),1562.2) -> 1562.2 | C8: =(B8-B7)/B7 -> -0.010608316
A9: =IFERROR(__xludf.DUMMYFUNCTION("""COMPUTED_VALUE"""),44384.6458333333) -> 44384.646 | B9: =IFERROR(__xludf.DUMMYFUNCTION("""COMPUTED_VALUE"""),1564.6) -> 1564.6 | C9: =(B9-B8)/B8 -> 0.001536295
A10: =IFERROR(__xludf.DUMMYFUNCTION("""COMPUTED_VALUE"""),44385.6458333333) -> 44385.646 | B10: =IFERROR(__xludf.DUMMYFUNCTION("""COMPUTED_VALUE"""),1560.75) -> 1560.75 | C10: =(B10-B9)/B9 -> -0.0024606928
A11: =IFERROR(__xludf.DUMMYFUNCTION("""COMPUTED_VALUE"""),44386.6458333333) -> 44386.646 | B11: =IFERROR(__xludf.DUMMYFUNCTION("""COMPUTED_VALUE"""),1562.9) -> 1562.9 | C11: =(B11-B10)/B10 -> 0.0013775428
A12: =IFERROR(__xludf.DUMMYFUNCTION("""COMPUTED_VALUE"""),44389.6458333333) -> 44389.646 | B12: =IFERROR(__xludf.DUMMYFUNCTION("""COMPUTED_VALUE"""),1547.85) -> 1547.85 | C12: =(B12-B11)/B11 -> -0.0096295348
A13: =IFERROR(__xludf.DUMMYFUNCTION("""COMPUTED_VALUE"""),44390.6458333333) -> 44390.646 | B13: =IFERROR(__xludf.DUMMYFUNCTION("""COMPUTED_VALUE"""),1544.95) -> 1544.95 | C13: =(B13-B12)/B12 -> -0.0018735666
A14: =IFERROR(__xludf.DUMMYFUNCTION("""COMPUTED_VALUE"""),44391.6458333333) -> 44391.646 | B14: =IFERROR(__xludf.DUMMYFUNCTION("""COMPUTED_VALUE"""),1576.9) -> 1576.9 | C14: =(B14-B13)/B13 -> 0.020680281
A15: =IFERROR(__xludf.DUMMYFUNCTION("""COMPUTED_VALUE"""),44392.6458333333) -> 44392.646 | B15: =IFERROR(__xludf.DUMMYFUNCTION("""COMPUTED_VALUE"""),1580.8) -> 1580.8 | C15: =(B15-B14)/B14 -> 0.0024732069
A16: =IFERROR(__xludf.DUMMYFUNCTION("""COMPUTED_VALUE"""),44393.6458333333) -> 44393.646 | B16: =IFERROR(__xludf.DUMMYFUNCTION("""COMPUTED_VALUE"""),1555.45) -> 1555.45 | C16: =(B16-B15)/B15 -> -0.016036184
A17: =IFERROR(__xludf.DUMMYFUNCTION("""COMPUTED_VALUE"""),44396.6458333333) -> 44396.646 | B17: =IFERROR(__xludf.DUMMYFUNCTION("""COMPUTED_VALUE"""),1541.7) -> 1541.7 | C17: =(B17-B16)/B16 -> -0.0088398856
A18: =IFERROR(__xludf.DUMMYFUNCTION("""COMPUTED_VALUE"""),44397.6458333333) -> 44397.646 | B18: =IFERROR(__xludf.DUMMYFUNCTION("""COMPUTED_VALUE"""),1550.05) -> 1550.05 | C18: =(B18-B17)/B17 -> 0.0054160991
A19: =IFERROR(__xludf.DUMMYFUNCTION("""COMPUTED_VALUE"""),44399.6458333333) -> 44399.646 | B19: =IFERROR(__xludf.DUMMYFUNCTION("""COMPUTED_VALUE"""),1590.2) -> 1590.2 | C19: =(B19-B18)/B18 -> 0.02590239
A20: =IFERROR(__xludf.DUMMYFUNCTION("""COMPUTED_VALUE"""),44400.6458333333) -> 44400.646 | B20: =IFERROR(__xludf.DUMMYFUNCTION("""COMPUTED_VALUE"""),1590.45) -> 1590.45 | C20: =(B20-B19)/B19 -> 0.00015721293
A21: =IFERROR(__xludf.DUMMYFUNCTION("""COMPUTED_VALUE"""),44403.6458333333) -> 44403.646 | B21: =IFERROR(__xludf.DUMMYFUNCTION("""COMPUTED_VALUE"""),1603.9) -> 1603.9 | C21: =(B21-B20)/B20 -> 0.0084567261
A22: =IFERROR(__xludf.DUMMYFUNCTION("""COMPUTED_VALUE"""),44404.6458333333) -> 44404.646 | B22: =IFERROR(__xludf.DUMMYFUNCTION("""COMPUTED_VALUE"""),1602.55) -> 1602.55 | C22: =(B22-B21)/B21 -> -0.00084169836
A23: =IFERROR(__xludf.DUMMYFUNCTION("""COMPUTED_VALUE"""),44405.6458333333) -> 44405.646 | B23: =IFERROR(__xludf.DUMMYFUNCTION("""COMPUTED_VALUE"""),1605.6) -> 1605.6 | C23: =(B23-B22)/B22 -> 0.0019032167
A24: =IFERROR(__xludf.DUMMYFUNCTION("""COMPUTED_VALUE"""),44406.6458333333) -> 44406.646 | B24: =IFERROR(__xludf.DUMMYFUNCTION("""COMPUTED_VALUE"""),1617) -> 1617 | C24: =(B24-B23)/B23 -> 0.0071001495
A25: =IFERROR(__xludf.DUMMYFUNCTION("""COMPUTED_VALUE"""),44407.6458333333) -> 44407.646 | B25: =IFERROR(__xludf.DUMMYFUNCTION("""COMPUTED_VALUE"""),1610.5) -> 1610.5 | C25: =(B25-B24)/B24 -> -0.0040197897
A26: =IFERROR(__xludf.DUMMYFUNCTION("""COMPUTED_VALUE"""),44410.6458333333) -> 44410.646 | B26: =IFERROR(__xludf.DUMMYFUNCTION("""COMPUTED_VALUE"""),1631.55) -> 1631.55 | C26: =(B26-B25)/B25 -> 0.013070475
A27: =IFERROR(__xludf.DUMMYFUNCTION("""COMPUTED_VALUE"""),44411.6458333333) -> 44411.646 | B27: =IFERROR(__xludf.DUMMYFUNCTION("""COMPUTED_VALUE"""),1655.2) -> 1655.2 | C27: =(B27-B26)/B26 -> 0.014495418
A28: =IFERROR(__xludf.DUMMYFUNCTION("""COMPUTED_VALUE"""),44412.6458333333) -> 44412.646 | B28: =IFERROR(__xludf.DUMMYFUNCTION("""COMPUTED_VALUE"""),1649.25) -> 1649.25 | C28: =(B28-B27)/B27 -> -0.0035947318
A29: =IFERROR(__xludf.DUMMYFUNCTION("""COMPUTED_VALUE"""),44413.6458333333) -> 44413.646 | B29: =IFERROR(__xludf.DUMMYFUNCTION("""COMPUTED_VALUE"""),1653.55) -> 1653.55 | C29: =(B29-B28)/B28 -> 0.0026072457
A30: =IFERROR(__xludf.DUMMYFUNCTION("""COMPUTED_VALUE"""),44414.6458333333) -> 44414.646 | B30: =IFERROR(__xludf.DUMMYFUNCTION("""COMPUTED_VALUE"""),1650.2) -> 1650.2 | C30: =(B30-B29)/B29 -> -0.0020259442
A31: =IFERROR(__xludf.DUMMYFUNCTION("""COMPUTED_VALUE"""),44417.6458333333) -> 44417.646 | B31: =IFERROR(__xludf.DUMMYFUNCTION("""COMPUTED_VALUE"""),1663.3) -> 1663.3 | C31: =(B31-B30)/B30 -> 0.0079384317
A32: =IFERROR(__xludf.DUMMYFUNCTION("""COMPUTED_VALUE"""),44418.6458333333) -> 44418.646 | B32: =IFERROR(__xludf.DUMMYFUNCTION("""COMPUTED_VALUE"""),1677.25) -> 1677.25 | C32: =(B32-B31)/B31 -> 0.0083869416
A33: =IFERROR(__xludf.DUMMYFUNCTION("""COMPUTED_VALUE"""),44419.6458333333) -> 44419.646 | B33: =IFERROR(__xludf.DUMMYFUNCTION("""COMPUTED_VALUE"""),1677.55) -> 1677.55 | C33: =(B33-B32)/B32 -> 0.00017886421
A34: =IFERROR(__xludf.DUMMYFUNCTION("""COMPUTED_VALUE"""),44420.6458333333) -> 44420.646 | B34: =IFERROR(__xludf.DUMMYFUNCTION("""COMPUTED_VALUE"""),1689.6) -> 1689.6 | C34: =(B34-B33)/B33 -> 0.0071830944
A35: =IFERROR(__xludf.DUMMYFUNCTION("""COMPUTED_VALUE"""),44421.6458333333) -> 44421.646 | B35: =IFERROR(__xludf.DUMMYFUNCTION("""COMPUTED_VALUE"""),1712.2) -> 1712.2 | C35: =(B35-B34)/B34 -> 0.013375947
A36: =IFERROR(__xludf.DUMMYFUNCTION("""COMPUTED_VALUE"""),44424.6458333333) -> 44424.646 | B36: =IFERROR(__xludf.DUMMYFUNCTION("""COMPUTED_VALUE"""),1704.4) -> 1704.4 | C36: =(B36-B35)/B35 -> -0.0045555426
A37: =IFERROR(__xludf.DUMMYFUNCTION("""COMPUTED_VALUE"""),44425.6458333333) -> 44425.646 | B37: =IFERROR(__xludf.DUMMYFUNCTION("""COMPUTED_VALUE"""),1741.65) -> 1741.65 | C37: =(B37-B36)/B36 -> 0.021855198
A38: =IFERROR(__xludf.DUMMYFUNCTION("""COMPUTED_VALUE"""),44426.6458333333) -> 44426.646 | B38: =IFERROR(__xludf.DUMMYFUNCTION("""COMPUTED_VALUE"""),1733.45) -> 1733.45 | C38: =(B38-B37)/B37 -> -0.004708179
A39: =IFERROR(__xludf.DUMMYFUNCTION("""COMPUTED_VALUE"""),44428.6458333333) -> 44428.646 | B39: =IFERROR(__xludf.DUMMYFUNCTION("""COMPUTED_VALUE"""),1732.95) -> 1732.95 | C39: =(B39-B38)/B38 -> -0.00028844212
A40: =IFERROR(__xludf.DUMMYFUNCTION("""COMPUTED_VALUE"""),44431.6458333333) -> 44431.646 | B40: =IFERROR(__xludf.DUMMYFUNCTION("""COMPUTED_VALUE"""),1738.75) -> 1738.75 | C40: =(B40-B39)/B39 -> 0.003346894
...

Sheet HDFC
A1: =IFERROR(__xludf.DUMMYFUNCTION("GOOGLEFINANCE(""NSE:HDFCBANK"", ""price"", TODAY()-1825, TODAY(), ""DAILY"")"),"Date") -> Date | B1: =IFERROR(__xludf.DUMMYFUNCTION("""COMPUTED_VALUE"""),"Close") -> Close | C1: Daily Return % | D1: 50-Day Moving Average (SMA) | E1: Annualized Volatility (Risk) | F1: Average Annual Return
A2: =IFERROR(__xludf.DUMMYFUNCTION("""COMPUTED_VALUE"""),44375.6458333333) -> 44375.646 | B2: =IFERROR(__xludf.DUMMYFUNCTION("""COMPUTED_VALUE"""),754.18) -> 754.18 | E2: =_xlfn.STDEV.S(C:C) * SQRT(252) -> 0.20937815 | F2: =AVERAGE(C:C)*252 -> 0.032279813
A3: =IFERROR(__xludf.DUMMYFUNCTION("""COMPUTED_VALUE"""),44376.6458333333) -> 44376.646 | B3: =IFERROR(__xludf.DUMMYFUNCTION("""COMPUTED_VALUE"""),751.03) -> 751.03 | C3: =(B3-B2)/B2 -> -0.0041767217
A4: =IFERROR(__xludf.DUMMYFUNCTION("""COMPUTED_VALUE"""),44377.6458333333) -> 44377.646 | B4: =IFERROR(__xludf.DUMMYFUNCTION("""COMPUTED_VALUE"""),748.95) -> 748.95 | C4: =(B4-B3)/B3 -> -0.0027695298
A5: =IFERROR(__xludf.DUMMYFUNCTION("""COMPUTED_VALUE"""),44378.6458333333) -> 44378.646 | B5: =IFERROR(__xludf.DUMMYFUNCTION("""COMPUTED_VALUE"""),743.38) -> 743.38 | C5: =(B5-B4)/B4 -> -0.0074370786
A6: =IFERROR(__xludf.DUMMYFUNCTION("""COMPUTED_VALUE"""),44379.6458333333) -> 44379.646 | B6: =IFERROR(__xludf.DUMMYFUNCTION("""COMPUTED_VALUE"""),740.2) -> 740.2 | C6: =(B6-B5)/B5 -> -0.0042777583
A7: =IFERROR(__xludf.DUMMYFUNCTION("""COMPUTED_VALUE"""),44382.6458333333) -> 44382.646 | B7: =IFERROR(__xludf.DUMMYFUNCTION("""COMPUTED_VALUE"""),747.73) -> 747.73 | C7: =(B7-B6)/B6 -> 0.010172926
A8: =IFERROR(__xludf.DUMMYFUNCTION("""COMPUTED_VALUE"""),44383.6458333333) -> 44383.646 | B8: =IFERROR(__xludf.DUMMYFUNCTION("""COMPUTED_VALUE"""),767.35) -> 767.35 | C8: =(B8-B7)/B7 -> 0.026239418
A9: =IFERROR(__xludf.DUMMYFUNCTION("""COMPUTED_VALUE"""),44384.6458333333) -> 44384.646 | B9: =IFERROR(__xludf.DUMMYFUNCTION("""COMPUTED_VALUE"""),769.75) -> 769.75 | C9: =(B9-B8)/B8 -> 0.0031276471
A10: =IFERROR(__xludf.DUMMYFUNCTION("""COMPUTED_VALUE"""),44385.6458333333) -> 44385.646 | B10: =IFERROR(__xludf.DUMMYFUNCTION("""COMPUTED_VALUE"""),760.23) -> 760.23 | C10: =(B10-B9)/B9 -> -0.012367652
A11: =IFERROR(__xludf.DUMMYFUNCTION("""COMPUTED_VALUE"""),44386.6458333333) -> 44386.646 | B11: =IFERROR(__xludf.DUMMYFUNCTION("""COMPUTED_VALUE"""),751) -> 751 | C11: =(B11-B10)/B10 -> -0.012141063
A12: =IFERROR(__xludf.DUMMYFUNCTION("""COMPUTED_VALUE"""),44389.6458333333) -> 44389.646 | B12: =IFERROR(__xludf.DUMMYFUNCTION("""COMPUTED_VALUE"""),743.5) -> 743.5 | C12: =(B12-B11)/B11 -> -0.0099866844
A13: =IFERROR(__xludf.DUMMYFUNCTION("""COMPUTED_VALUE"""),44390.6458333333) -> 44390.646 | B13: =IFERROR(__xludf.DUMMYFUNCTION("""COMPUTED_VALUE"""),750.93) -> 750.93 | C13: =(B13-B12)/B12 -> 0.0099932751
A14: =IFERROR(__xludf.DUMMYFUNCTION("""COMPUTED_VALUE"""),44391.6458333333) -> 44391.646 | B14: =IFERROR(__xludf.DUMMYFUNCTION("""COMPUTED_VALUE"""),749.58) -> 749.58 | C14: =(B14-B13)/B13 -> -0.0017977708
A15: =IFERROR(__xludf.DUMMYFUNCTION("""COMPUTED_VALUE"""),44392.6458333333) -> 44392.646 | B15: =IFERROR(__xludf.DUMMYFUNCTION("""COMPUTED_VALUE"""),760.35) -> 760.35 | C15: =(B15-B14)/B14 -> 0.014368046
A16: =IFERROR(__xludf.DUMMYFUNCTION("""COMPUTED_VALUE"""),44393.6458333333) -> 44393.646 | B16: =IFERROR(__xludf.DUMMYFUNCTION("""COMPUTED_VALUE"""),761.18) -> 761.18 | C16: =(B16-B15)/B15 -> 0.0010916026
A17: =IFERROR(__xludf.DUMMYFUNCTION("""COMPUTED_VALUE"""),44396.6458333333) -> 44396.646 | B17: =IFERROR(__xludf.DUMMYFUNCTION("""COMPUTED_VALUE"""),735.5) -> 735.5 | C17: =(B17-B16)/B16 -> -0.033737092
A18: =IFERROR(__xludf.DUMMYFUNCTION("""COMPUTED_VALUE"""),44397.6458333333) -> 44397.646 | B18: =IFERROR(__xludf.DUMMYFUNCTION("""COMPUTED_VALUE"""),721.58) -> 721.58 | C18: =(B18-B17)/B17 -> -0.018925901
A19: =IFERROR(__xludf.DUMMYFUNCTION("""COMPUTED_VALUE"""),44399.6458333333) -> 44399.646 | B19: =IFERROR(__xludf.DUMMYFUNCTION("""COMPUTED_VALUE"""),724.35) -> 724.35 | C19: =(B19-B18)/B18 -> 0.0038387982
A20: =IFERROR(__xludf.DUMMYFUNCTION("""COMPUTED_VALUE"""),44400.6458333333) -> 44400.646 | B20: =IFERROR(__xludf.DUMMYFUNCTION("""COMPUTED_VALUE"""),721.38) -> 721.38 | C20: =(B20-B19)/B19 -> -0.0041002278
A21: =IFERROR(__xludf.DUMMYFUNCTION("""COMPUTED_VALUE"""),44403.6458333333) -> 44403.646 | B21: =IFERROR(__xludf.DUMMYFUNCTION("""COMPUTED_VALUE"""),717.28) -> 717.28 | C21: =(B21-B20)/B20 -> -0.005683551
A22: =IFERROR(__xludf.DUMMYFUNCTION("""COMPUTED_VALUE"""),44404.6458333333) -> 44404.646 | B22: =IFERROR(__xludf.DUMMYFUNCTION("""COMPUTED_VALUE"""),719.88) -> 719.88 | C22: =(B22-B21)/B21 -> 0.0036248048
A23: =IFERROR(__xludf.DUMMYFUNCTION("""COMPUTED_VALUE"""),44405.6458333333) -> 44405.646 | B23: =IFERROR(__xludf.DUMMYFUNCTION("""COMPUTED_VALUE"""),708.65) -> 708.65 | C23: =(B23-B22)/B22 -> -0.015599822
A24: =IFERROR(__xludf.DUMMYFUNCTION("""COMPUTED_VALUE"""),44406.6458333333) -> 44406.646 | B24: =IFERROR(__xludf.DUMMYFUNCTION("""COMPUTED_VALUE"""),709.13) -> 709.13 | C24: =(B24-B23)/B23 -> 0.00067734425
A25: =IFERROR(__xludf.DUMMYFUNCTION("""COMPUTED_VALUE"""),44407.6458333333) -> 44407.646 | B25: =IFERROR(__xludf.DUMMYFUNCTION("""COMPUTED_VALUE"""),713.23) -> 713.23 | C25: =(B25-B24)/B24 -> 0.0057817325
A26: =IFERROR(__xludf.DUMMYFUNCTION("""COMPUTED_VALUE"""),44410.6458333333) -> 44410.646 | B26: =IFERROR(__xludf.DUMMYFUNCTION("""COMPUTED_VALUE"""),711.33) -> 711.33 | C26: =(B26-B25)/B25 -> -0.0026639373
A27: =IFERROR(__xludf.DUMMYFUNCTION("""COMPUTED_VALUE"""),44411.6458333333) -> 44411.646 | B27: =IFERROR(__xludf.DUMMYFUNCTION("""COMPUTED_VALUE"""),717.35) -> 717.35 | C27: =(B27-B26)/B26 -> 0.00846302
A28: =IFERROR(__xludf.DUMMYFUNCTION("""COMPUTED_VALUE"""),44412.6458333333) -> 44412.646 | B28: =IFERROR(__xludf.DUMMYFUNCTION("""COMPUTED_VALUE"""),732.65) -> 732.65 | C28: =(B28-B27)/B27 -> 0.021328501
A29: =IFERROR(__xludf.DUMMYFUNCTION("""COMPUTED_VALUE"""),44413.6458333333) -> 44413.646 | B29: =IFERROR(__xludf.DUMMYFUNCTION("""COMPUTED_VALUE"""),742.43) -> 742.43 | C29: =(B29-B28)/B28 -> 0.013348802
A30: =IFERROR(__xludf.DUMMYFUNCTION("""COMPUTED_VALUE"""),44414.6458333333) -> 44414.646 | B30: =IFERROR(__xludf.DUMMYFUNCTION("""COMPUTED_VALUE"""),746.33) -> 746.33 | C30: =(B30-B29)/B29 -> 0.0052530205
A31: =IFERROR(__xludf.DUMMYFUNCTION("""COMPUTED_VALUE"""),44417.6458333333) -> 44417.646 | B31: =IFERROR(__xludf.DUMMYFUNCTION("""COMPUTED_VALUE"""),751.95) -> 751.95 | C31: =(B31-B30)/B30 -> 0.007530181
A32: =IFERROR(__xludf.DUMMYFUNCTION("""COMPUTED_VALUE"""),44418.6458333333) -> 44418.646 | B32: =IFERROR(__xludf.DUMMYFUNCTION("""COMPUTED_VALUE"""),753.83) -> 753.83 | C32: =(B32-B31)/B31 -> 0.0025001662
A33: =IFERROR(__xludf.DUMMYFUNCTION("""COMPUTED_VALUE"""),44419.6458333333) -> 44419.646 | B33: =IFERROR(__xludf.DUMMYFUNCTION("""COMPUTED_VALUE"""),747.48) -> 747.48 | C33: =(B33-B32)/B32 -> -0.0084236499
A34: =IFERROR(__xludf.DUMMYFUNCTION("""COMPUTED_VALUE"""),44420.6458333333) -> 44420.646 | B34: =IFERROR(__xludf.DUMMYFUNCTION("""COMPUTED_VALUE"""),750.7) -> 750.7 | C34: =(B34-B33)/B33 -> 0.0043078076
A35: =IFERROR(__xludf.DUMMYFUNCTION("""COMPUTED_VALUE"""),44421.6458333333) -> 44421.646 | B35: =IFERROR(__xludf.DUMMYFUNCTION("""COMPUTED_VALUE"""),763.1) -> 763.1 | C35: =(B35-B34)/B34 -> 0.016517917
A36: =IFERROR(__xludf.DUMMYFUNCTION("""COMPUTED_VALUE"""),44424.6458333333) -> 44424.646 | B36: =IFERROR(__xludf.DUMMYFUNCTION("""COMPUTED_VALUE"""),765.3) -> 765.3 | C36: =(B36-B35)/B35 -> 0.0028829773
A37: =IFERROR(__xludf.DUMMYFUNCTION("""COMPUTED_VALUE"""),44425.6458333333) -> 44425.646 | B37: =IFERROR(__xludf.DUMMYFUNCTION("""COMPUTED_VALUE"""),757.33) -> 757.33 | C37: =(B37-B36)/B36 -> -0.010414217
A38: =IFERROR(__xludf.DUMMYFUNCTION("""COMPUTED_VALUE"""),44426.6458333333) -> 44426.646 | B38: =IFERROR(__xludf.DUMMYFUNCTION("""COMPUTED_VALUE"""),756.5) -> 756.5 | C38: =(B38-B37)/B37 -> -0.0010959555
A39: =IFERROR(__xludf.DUMMYFUNCTION("""COMPUTED_VALUE"""),44428.6458333333) -> 44428.646 | B39: =IFERROR(__xludf.DUMMYFUNCTION("""COMPUTED_VALUE"""),757.38) -> 757.38 | C39: =(B39-B38)/B38 -> 0.0011632518
A40: =IFERROR(__xludf.DUMMYFUNCTION("""COMPUTED_VALUE"""),44431.6458333333) -> 44431.646 | B40: =IFERROR(__xludf.DUMMYFUNCTION("""COMPUTED_VALUE"""),762.3) -> 762.3 | C40: =(B40-B39)/B39 -> 0.0064960786
...

Sheet ICICI
A1: =IFERROR(__xludf.DUMMYFUNCTION("GOOGLEFINANCE(""NSE:ICICIBANK"", ""price"", TODAY()-1825, TODAY(), ""DAILY"")"),"Date") -> Date | B1: =IFERROR(__xludf.DUMMYFUNCTION("""COMPUTED_VALUE"""),"Close") -> Close | C1: Daily Return % | D1: 50-Day Moving Average (SMA) | E1: Annualized Volatility (Risk) | F1: Average Annual Return
A2: =IFERROR(__xludf.DUMMYFUNCTION("""COMPUTED_VALUE"""),44375.6458333333) -> 44375.646 | B2: =IFERROR(__xludf.DUMMYFUNCTION("""COMPUTED_VALUE"""),650.3) -> 650.3 | E2: =_xlfn.STDEV.S(C:C) * SQRT(252) -> 0.20404637 | F2: =AVERAGE(C:C)*252 -> 0.174235
A3: =IFERROR(__xludf.DUMMYFUNCTION("""COMPUTED_VALUE"""),44376.6458333333) -> 44376.646 | B3: =IFERROR(__xludf.DUMMYFUNCTION("""COMPUTED_VALUE"""),640.1) -> 640.1 | C3: =(B3-B2)/B2 -> -0.015685068
A4: =IFERROR(__xludf.DUMMYFUNCTION("""COMPUTED_VALUE"""),44377.6458333333) -> 44377.646 | B4: =IFERROR(__xludf.DUMMYFUNCTION("""COMPUTED_VALUE"""),630.9) -> 630.9 | C4: =(B4-B3)/B3 -> -0.014372754
A5: =IFERROR(__xludf.DUMMYFUNCTION("""COMPUTED_VALUE"""),44378.6458333333) -> 44378.646 | B5: =IFERROR(__xludf.DUMMYFUNCTION("""COMPUTED_VALUE"""),630.85) -> 630.85 | C5: =(B5-B4)/B4 -> -7.9251862e-05
A6: =IFERROR(__xludf.DUMMYFUNCTION("""COMPUTED_VALUE"""),44379.6458333333) -> 44379.646 | B6: =IFERROR(__xludf.DUMMYFUNCTION("""COMPUTED_VALUE"""),640.25) -> 640.25 | C6: =(B6-B5)/B5 -> 0.014900531
A7: =IFERROR(__xludf.DUMMYFUNCTION("""COMPUTED_VALUE"""),44382.6458333333) -> 44382.646 | B7: =IFERROR(__xludf.DUMMYFUNCTION("""COMPUTED_VALUE"""),647.85) -> 647.85 | C7: =(B7-B6)/B6 -> 0.011870363
A8: =IFERROR(__xludf.DUMMYFUNCTION("""COMPUTED_VALUE"""),44383.6458333333) -> 44383.646 | B8: =IFERROR(__xludf.DUMMYFUNCTION("""COMPUTED_VALUE"""),650.3) -> 650.3 | C8: =(B8-B7)/B7 -> 0.0037817396
A9: =IFERROR(__xludf.DUMMYFUNCTION("""COMPUTED_VALUE"""),44384.6458333333) -> 44384.646 | B9: =IFERROR(__xludf.DUMMYFUNCTION("""COMPUTED_VALUE"""),654) -> 654 | C9: =(B9-B8)/B8 -> 0.0056896817
A10: =IFERROR(__xludf.DUMMYFUNCTION("""COMPUTED_VALUE"""),44385.6458333333) -> 44385.646 | B10: =IFERROR(__xludf.DUMMYFUNCTION("""COMPUTED_VALUE"""),641.9) -> 641.9 | C10: =(B10-B9)/B9 -> -0.018501529
A11: =IFERROR(__xludf.DUMMYFUNCTION("""COMPUTED_VALUE"""),44386.6458333333) -> 44386.646 | B11: =IFERROR(__xludf.DUMMYFUNCTION("""COMPUTED_VALUE"""),638.55) -> 638.55 | C11: =(B11-B10)/B10 -> -0.0052188814
A12: =IFERROR(__xludf.DUMMYFUNCTION("""COMPUTED_VALUE"""),44389.6458333333) -> 44389.646 | B12: =IFERROR(__xludf.DUMMYFUNCTION("""COMPUTED_VALUE"""),646.25) -> 646.25 | C12: =(B12-B11)/B11 -> 0.01205857
A13: =IFERROR(__xludf.DUMMYFUNCTION("""COMPUTED_VALUE"""),44390.6458333333) -> 44390.646 | B13: =IFERROR(__xludf.DUMMYFUNCTION("""COMPUTED_VALUE"""),664.95) -> 664.95 | C13: =(B13-B12)/B12 -> 0.02893617
A14: =IFERROR(__xludf.DUMMYFUNCTION("""COMPUTED_VALUE"""),44391.6458333333) -> 44391.646 | B14: =IFERROR(__xludf.DUMMYFUNCTION("""COMPUTED_VALUE"""),664.35) -> 664.35 | C14: =(B14-B13)/B13 -> -0.00090232348
A15: =IFERROR(__xludf.DUMMYFUNCTION("""COMPUTED_VALUE"""),44392.6458333333) -> 44392.646 | B15: =IFERROR(__xludf.DUMMYFUNCTION("""COMPUTED_VALUE"""),667.45) -> 667.45 | C15: =(B15-B14)/B14 -> 0.0046662151
A16: =IFERROR(__xludf.DUMMYFUNCTION("""COMPUTED_VALUE"""),44393.6458333333) -> 44393.646 | B16: =IFERROR(__xludf.DUMMYFUNCTION("""COMPUTED_VALUE"""),660.3) -> 660.3 | C16: =(B16-B15)/B15 -> -0.010712413
A17: =IFERROR(__xludf.DUMMYFUNCTION("""COMPUTED_VALUE"""),44396.6458333333) -> 44396.646 | B17: =IFERROR(__xludf.DUMMYFUNCTION("""COMPUTED_VALUE"""),655.9) -> 655.9 | C17: =(B17-B16)/B16 -> -0.0066636377
A18: =IFERROR(__xludf.DUMMYFUNCTION("""COMPUTED_VALUE"""),44397.6458333333) -> 44397.646 | B18: =IFERROR(__xludf.DUMMYFUNCTION("""COMPUTED_VALUE"""),641.9) -> 641.9 | C18: =(B18-B17)/B17 -> -0.021344717
A19: =IFERROR(__xludf.DUMMYFUNCTION("""COMPUTED_VALUE"""),44399.6458333333) -> 44399.646 | B19: =IFERROR(__xludf.DUMMYFUNCTION("""COMPUTED_VALUE"""),655.95) -> 655.95 | C19: =(B19-B18)/B18 -> 0.021888145
A20: =IFERROR(__xludf.DUMMYFUNCTION("""COMPUTED_VALUE"""),44400.6458333333) -> 44400.646 | B20: =IFERROR(__xludf.DUMMYFUNCTION("""COMPUTED_VALUE"""),676.65) -> 676.65 | C20: =(B20-B19)/B19 -> 0.031557283
A21: =IFERROR(__xludf.DUMMYFUNCTION("""COMPUTED_VALUE"""),44403.6458333333) -> 44403.646 | B21: =IFERROR(__xludf.DUMMYFUNCTION("""COMPUTED_VALUE"""),676.75) -> 676.75 | C21: =(B21-B20)/B20 -> 0.00014778689
A22: =IFERROR(__xludf.DUMMYFUNCTION("""COMPUTED_VALUE"""),44404.6458333333) -> 44404.646 | B22: =IFERROR(__xludf.DUMMYFUNCTION("""COMPUTED_VALUE"""),677.45) -> 677.45 | C22: =(B22-B21)/B21 -> 0.0010343554
A23: =IFERROR(__xludf.DUMMYFUNCTION("""COMPUTED_VALUE"""),44405.6458333333) -> 44405.646 | B23: =IFERROR(__xludf.DUMMYFUNCTION("""COMPUTED_VALUE"""),685.05) -> 685.05 | C23: =(B23-B22)/B22 -> 0.01121854
A24: =IFERROR(__xludf.DUMMYFUNCTION("""COMPUTED_VALUE"""),44406.6458333333) -> 44406.646 | B24: =IFERROR(__xludf.DUMMYFUNCTION("""COMPUTED_VALUE"""),687.5) -> 687.5 | C24: =(B24-B23)/B23 -> 0.0035763813
A25: =IFERROR(__xludf.DUMMYFUNCTION("""COMPUTED_VALUE"""),44407.6458333333) -> 44407.646 | B25: =IFERROR(__xludf.DUMMYFUNCTION("""COMPUTED_VALUE"""),682.5) -> 682.5 | C25: =(B25-B24)/B24 -> -0.0072727273
A26: =IFERROR(__xludf.DUMMYFUNCTION("""COMPUTED_VALUE"""),44410.6458333333) -> 44410.646 | B26: =IFERROR(__xludf.DUMMYFUNCTION("""COMPUTED_VALUE"""),681.4) -> 681.4 | C26: =(B26-B25)/B25 -> -0.0016117216
A27: =IFERROR(__xludf.DUMMYFUNCTION("""COMPUTED_VALUE"""),44411.6458333333) -> 44411.646 | B27: =IFERROR(__xludf.DUMMYFUNCTION("""COMPUTED_VALUE"""),690.4) -> 690.4 | C27: =(B27-B26)/B26 -> 0.013208101
A28: =IFERROR(__xludf.DUMMYFUNCTION("""COMPUTED_VALUE"""),44412.6458333333) -> 44412.646 | B28: =IFERROR(__xludf.DUMMYFUNCTION("""COMPUTED_VALUE"""),714.65) -> 714.65 | C28: =(B28-B27)/B27 -> 0.035124565
A29: =IFERROR(__xludf.DUMMYFUNCTION("""COMPUTED_VALUE"""),44413.6458333333) -> 44413.646 | B29: =IFERROR(__xludf.DUMMYFUNCTION("""COMPUTED_VALUE"""),702.45) -> 702.45 | C29: =(B29-B28)/B28 -> -0.017071294
A30: =IFERROR(__xludf.DUMMYFUNCTION("""COMPUTED_VALUE"""),44414.6458333333) -> 44414.646 | B30: =IFERROR(__xludf.DUMMYFUNCTION("""COMPUTED_VALUE"""),697.65) -> 697.65 | C30: =(B30-B29)/B29 -> -0.0068332266
A31: =IFERROR(__xludf.DUMMYFUNCTION("""COMPUTED_VALUE"""),44417.6458333333) -> 44417.646 | B31: =IFERROR(__xludf.DUMMYFUNCTION("""COMPUTED_VALUE"""),702.85) -> 702.85 | C31: =(B31-B30)/B30 -> 0.0074535942
A32: =IFERROR(__xludf.DUMMYFUNCTION("""COMPUTED_VALUE"""),44418.6458333333) -> 44418.646 | B32: =IFERROR(__xludf.DUMMYFUNCTION("""COMPUTED_VALUE"""),700.9) -> 700.9 | C32: =(B32-B31)/B31 -> -0.0027744184
A33: =IFERROR(__xludf.DUMMYFUNCTION("""COMPUTED_VALUE"""),44419.6458333333) -> 44419.646 | B33: =IFERROR(__xludf.DUMMYFUNCTION("""COMPUTED_VALUE"""),693.55) -> 693.55 | C33: =(B33-B32)/B32 -> -0.010486517
A34: =IFERROR(__xludf.DUMMYFUNCTION("""COMPUTED_VALUE"""),44420.6458333333) -> 44420.646 | B34: =IFERROR(__xludf.DUMMYFUNCTION("""COMPUTED_VALUE"""),701.35) -> 701.35 | C34: =(B34-B33)/B33 -> 0.011246485
A35: =IFERROR(__xludf.DUMMYFUNCTION("""COMPUTED_VALUE"""),44421.6458333333) -> 44421.646 | B35: =IFERROR(__xludf.DUMMYFUNCTION("""COMPUTED_VALUE"""),704.8) -> 704.8 | C35: =(B35-B34)/B34 -> 0.0049190846
A36: =IFERROR(__xludf.DUMMYFUNCTION("""COMPUTED_VALUE"""),44424.6458333333) -> 44424.646 | B36: =IFERROR(__xludf.DUMMYFUNCTION("""COMPUTED_VALUE"""),702.65) -> 702.65 | C36: =(B36-B35)/B35 -> -0.0030505108
A37: =IFERROR(__xludf.DUMMYFUNCTION("""COMPUTED_VALUE"""),44425.6458333333) -> 44425.646 | B37: =IFERROR(__xludf.DUMMYFUNCTION("""COMPUTED_VALUE"""),701.2) -> 701.2 | C37: =(B37-B36)/B36 -> -0.0020636163
A38: =IFERROR(__xludf.DUMMYFUNCTION("""COMPUTED_VALUE"""),44426.6458333333) -> 44426.646 | B38: =IFERROR(__xludf.DUMMYFUNCTION("""COMPUTED_VALUE"""),688.3) -> 688.3 | C38: =(B38-B37)/B37 -> -0.018397034
A39: =IFERROR(__xludf.DUMMYFUNCTION("""COMPUTED_VALUE"""),44428.6458333333) -> 44428.646 | B39: =IFERROR(__xludf.DUMMYFUNCTION("""COMPUTED_VALUE"""),680.7) -> 680.7 | C39: =(B39-B38)/B38 -> -0.011041697
A40: =IFERROR(__xludf.DUMMYFUNCTION("""COMPUTED_VALUE"""),44431.6458333333) -> 44431.646 | B40: =IFERROR(__xludf.DUMMYFUNCTION("""COMPUTED_VALUE"""),682.7) -> 682.7 | C40: =(B40-B39)/B39 -> 0.0029381519
...
